<?xml version="1.0"?>
<robot xmlns:xacro="http://www.ros.org/wiki/xacro" name="wheel">

  <!-- Define the wheel link -->
  <link name="${name}_link">
    <inertial>
      <mass value="1.0"/>
      <origin xyz="0 0 0" rpy="0 1.5707 1.5707"/>
      <inertia ixx="0.005" ixy="0" ixz="0" iyy="0.005" iyz="0" izz="0.005"/>
    </inertial>
    <visual>
      <origin xyz="0 0 0" rpy="0 0 0"/>
      <geometry>
        <cylinder radius="${robot_wheel_radius}" length="${robot_wheel_radius}"/>
      </geometry>
      <material name="black">
        <color rgba="0 0 0 1"/>
      </material>
    </visual>
  </link>

  <!-- Define the wheel joint -->
  <joint name="${name}_joint" type="continuous">
    <origin xyz="${x} ${y} 0" rpy="0 0 0"/>
    <parent link="${parent}"/>
    <child link="${name}_link"/>
    <axis xyz="0 1 0"/>
    <limit effort="10000" velocity="1000" />
	  <dynamics damping="1.0" friction="1.0" />
  </joint>

	<gazebo reference="${name}_link">
		<material>Gazebo/Green</material>
		<kp>1000000.0</kp> <!-- kp and kd for rubber -->
		<kd>100.0</kd>
		<mu1>1.0</mu1>
		<mu2>1.0</mu2>
		<maxVel>1.0</maxVel>
		<minDepth>0.00</minDepth>
	</gazebo>

</robot>
